Workbook

Sheet Overview
A1: ABA Opportunity Reports & Dashboards – Filter Criteria
A2: Generated from the deployed Salesforce metadata and live data in org ABA_Dev.
A4: Setting | B4: Value | C4: Note
A5: As of date | B5: 46303 | C5: Date the live data was read. Relative date filters (this month, current FY, next 30 days) resolve against this date. Change it to recalculate Age on the Opportunity Data sheet.
A6: Org | B6: ABA_Dev (00DgK00000bWvvVUAS) | C6: Developer Edition
A7: Fiscal year | B7: Standard, January – December | C7: Fiscal quarters equal calendar quarters
A8: Currency | B8: Amounts are SAR values from the sample CSV | C8: Org currency is USD, so Salesforce shows a $ sign
A9: Report type | B9: Opportunities (standard) | C9: All reports use Show Me = All opportunities (scope: organization)
A11: Sheet | B11: What it shows
A12: Report Catalog | B12: One row per report: purpose, folder, format, every filter, grouping, column, summary, chart and sort, and where it is used.
A13: Report Filters | B13: One row per filter condition per report, including the standard Opportunity Status and date-range filters and the filter logic.
A14: Report Fields | B14: One row per field per report, and its role (filter, date filter, row or column grouping, detail column, summary, chart).
A15: Field Usage Matrix | B15: Every field against every report, showing where each field is used.
A16: Dashboards | B16: Dashboard-level settings: folder, running user, grid, and dashboard filters with all their options.
A17: Dashboard Components | B17: One row per component: position on the grid, type, source report and that report's filters, measure, groupings, sort, gauge bands, table columns and current value.
A18: Home Page | B18: Sales app Home page regions and their components.
A19: Opportunity Data | B19: Every opportunity in the org with all reporting fields, plus a 1/0 flag showing whether it is included in each report.
A20: Report Results | B20: Record count and amount for each report, calculated with formulas from the flags, alongside the live count from Salesforce.
A21: Folders & Access | B21: Report and dashboard folders and who they are shared with.
A23: Legend | B23: Yellow fill and blue text = input you can change. Black text = formula or text taken from Salesforce.

Sheet Report Catalog
A1: Report ID | B1: Report name | C1: Column1 | D1: Column2 | E1: Column3 | F1: Column4 | G1: Description | H1: Format | I1: Report type | J1: Show Me (scope) | K1: Opportunity Status | L1: Date field | M1: Date range | N1: Date range resolved (as of 8 Oct 2026) | O1: Field filters | P1: Filter logic | Q1: Group rows by | R1: Group columns by | S1: Detail columns | T1: Summaries | U1: Custom summary formula | V1: Row limit | W1: Sort | X1: Report chart | Y1: Show details / subtotals / grand total | Z1: Used in dashboards & Home page | AA1: Salesforce report ID
A2: R01 | B2: Revenue Won – YTD by Quarter & Month | G2: Closed Won revenue this fiscal year by fiscal quarter and month. | H2: Summary | I2: Opportunity | J2: All opportunities | K2: All Opportunities | L2: Close Date | M2: Current FY | N2: 1 Jan 2026 – 31 Dec 2026 | O2: 1. Stage equals "Closed Won" | P2: AND (all conditions) | Q2: Close Date (Fiscal Quarter) → Close Month (Calendar Month) | R2: – | S2: Opportunity Name, Account Name, Opportunity Owner, Type, Amount | T2: Sum of Amount, Record Count | U2: – | V2: None | W2: Default | X2: VerticalColumn · X: Close Date · Y: Sum of Amount | Y2: true / true / true | Z2: D1: Revenue Won – YTD Home page (sidebar): report chart | AA2: 00OgK00000EysQTUAZ
A3: R02 | B3: Revenue Won – This Month (MTD) | G3: Closed Won revenue this month by salesperson. | H3: Summary | I3: Opportunity | J3: All opportunities | K3: All Opportunities | L3: Close Date | M3: Current Calendar Month | N3: 1 Oct 2026 – 31 Oct 2026 | O3: 1. Stage equals "Closed Won" | P3: AND (all conditions) | Q3: Opportunity Owner | R3: – | S3: Opportunity Name, Account Name, Amount, Close Date | T3: Sum of Amount, Record Count | U3: – | V3: None | W3: Default | X3: No chart | Y3: true / true / true | Z3: D1: Revenue Won – MTD | AA3: 00OgK00000EysQUUAZ
A4: R03 | B4: Revenue Won – This Quarter (QTD) | G4: Closed Won revenue this fiscal quarter by salesperson (gauge vs quarterly target). | H4: Summary | I4: Opportunity | J4: All opportunities | K4: All Opportunities | L4: Close Date | M4: Current FQ | N4: 1 Oct 2026 – 31 Dec 2026 | O4: 1. Stage equals "Closed Won" | P4: AND (all conditions) | Q4: Opportunity Owner | R4: – | S4: Opportunity Name, Account Name, Amount, Close Date | T4: Sum of Amount, Record Count | U4: – | V4: None | W4: Default | X4: No chart | Y4: true / true / true | Z4: D1: Revenue Won – QTD vs Target | AA4: 00OgK00000EysQVUAZ
A5: R04 | B5: Revenue Won – This Year vs Last Year | G5: Closed Won revenue by quarter, current vs previous fiscal year. | H5: Matrix | I5: Opportunity | J5: All opportunities | K5: All Opportunities | L5: Close Date | M5: Previous FY + Current FY | N5: 1 Jan 2025 – 31 Dec 2026 | O5: 1. Stage equals "Closed Won" | P5: AND (all conditions) | Q5: Close Quarter | R5: Close Date (Fiscal Year) | S5: Amount | T5: Sum of Amount, Record Count | U5: – | V5: None | W5: Default | X5: VerticalColumnGrouped · X: Close Quarter · Series: Close Date · Y: Sum of Amount · Legend Right | Y5: true / true / true | Z5: D1: Revenue by Quarter – This Year vs Last Year | AA5: 00OgK00000EysQWUAZ
A6: R05 | B6: Open Pipeline by Stage | G6: Active open pipeline by stage (excludes Deferred and Old / Archived). | H6: Summary | I6: Opportunity | J6: All opportunities | K6: Open Opportunities | L6: Close Date | M6: All Time | N6: No date limit (custom range left empty) | O6: 1. Stage not equal to "Deferred,Old / Archived" | P6: AND (all conditions) | Q6: Stage | R6: – | S6: Opportunity Name, Account Name, Opportunity Owner, Amount, Probability (%), Expected Revenue, Close Date, Next Step | T6: Sum of Amount, Sum of Expected Revenue, Record Count | U6: – | V6: None | W6: Default | X6: Funnel · X: Stage · Y: Sum of Amount · Legend Right | Y6: true / true / true | Z6: D1: Open Pipeline Value D1: Pipeline by Stage Home page (bottomLeft): report chart | AA6: 00OgK00000EysQXUAZ
A7: R06 | B7: Pipeline by Close Quarter (Next 4) | G7: Active open pipeline closing this and the next 3 fiscal quarters, by forecast category. | H7: Matrix | I7: Opportunity | J7: All opportunities | K7: Open Opportunities | L7: Close Date | M7: Current FQ + Next 3 FQ | N7: 1 Oct 2026 – 30 Sep 2027 | O7: 1. Stage not equal to "Deferred,Old / Archived" | P7: AND (all conditions) | Q7: Close Date (Fiscal Quarter) | R7: Forecast Category | S7: Amount | T7: Sum of Amount, Record Count | U7: – | V7: None | W7: Default | X7: VerticalColumnStacked · X: Close Date · Series: Forecast Category · Y: Sum of Amount · Legend Right | Y7: true / true / true | Z7: D1: Pipeline by Close Quarter | AA7: 00OgK00000EysQYUAZ
A8: R07 | B8: Pipeline by Salesperson & Stage | G8: Active open pipeline by salesperson and stage. | H8: Matrix | I8: Opportunity | J8: All opportunities | K8: Open Opportunities | L8: Close Date | M8: All Time | N8: No date limit (custom range left empty) | O8: 1. Stage not equal to "Deferred,Old / Archived" | P8: AND (all conditions) | Q8: Opportunity Owner | R8: Stage | S8: Amount | T8: Sum of Amount, Record Count | U8: – | V8: None | W8: Default | X8: HorizontalBarStacked · X: Opportunity Owner · Series: Stage · Y: Sum of Amount · Legend Right | Y8: true / true / true | Z8: D2: Pipeline by Salesperson & Stage | AA8: 00OgK00000EysQcUAJ
A9: R08 | B9: Revenue Won by Salesperson – YTD | G9: Leaderboard: Closed Won revenue this fiscal year by salesperson. | H9: Summary | I9: Opportunity | J9: All opportunities | K9: All Opportunities | L9: Close Date | M9: Current FY | N9: 1 Jan 2026 – 31 Dec 2026 | O9: 1. Stage equals "Closed Won" | P9: AND (all conditions) | Q9: Opportunity Owner, sorted by aggregate Amount desc | R9: – | S9: Opportunity Name, Account Name, Amount, Close Date | T9: Sum of Amount, Record Count | U9: – | V9: None | W9: Default | X9: HorizontalBar · X: Opportunity Owner · Y: Sum of Amount | Y9: true / true / true | Z9: D2: Revenue Won by Salesperson Home page (sidebar): report chart | AA9: 00OgK00000EysQdUAJ
A10: R09 | B10: Win Rate by Salesperson – YTD | G10: Win rate (won / closed) this fiscal year by salesperson. | H10: Summary | I10: Opportunity | J10: All opportunities | K10: Closed Opportunities | L10: Close Date | M10: Current FY | N10: 1 Jan 2026 – 31 Dec 2026 | O10: None | P10: AND (all conditions) | Q10: Opportunity Owner | R10: – | S10: Opportunity Name, Stage, Amount, Won, Closed | T10: Sum of Amount, Record Count | U10: Win Rate % = WON:SUM / CLOSED:SUM (percent, 0 dp) | V10: None | W10: Default | X10: No chart | Y10: true / true / true | Z10: D1: Win Rate YTD D2: Win Rate by Salesperson | AA10: 00OgK00000EysQeUAJ
A11: R10 | B11: Win-Loss Analysis by Reason – YTD | G11: Closed opportunities this fiscal year by outcome and win/loss reason. | H11: Summary | I11: Opportunity | J11: All opportunities | K11: Closed Opportunities | L11: Close Date | M11: Current FY | N11: 1 Jan 2026 – 31 Dec 2026 | O11: None | P11: AND (all conditions) | Q11: Stage → Win/Loss Reason | R11: – | S11: Opportunity Name, Account Name, Opportunity Owner, Amount, Win/Loss Details | T11: Sum of Amount, Record Count | U11: – | V11: None | W11: Default | X11: HorizontalBarStacked · X: Stage · Series: Win/Loss Reason · Y: Sum of Amount · Legend Right | Y11: true / true / true | Z11: Report only | AA11: 00OgK00000EysQhUAJ
A12: R10a | B12: Why We Win – YTD | G12: Dashboard source: Closed Won this fiscal year by win reason. | H12: Summary | I12: Opportunity | J12: All opportunities | K12: All Opportunities | L12: Close Date | M12: Current FY | N12: 1 Jan 2026 – 31 Dec 2026 | O12: 1. Stage equals "Closed Won" | P12: AND (all conditions) | Q12: Win/Loss Reason | R12: – | S12: Opportunity Name, Account Name, Opportunity Owner, Amount, Win/Loss Details | T12: Sum of Amount, Record Count | U12: – | V12: None | W12: Default | X12: Donut · X: Win/Loss Reason · Y: Sum of Amount · Legend Right | Y12: true / true / true | Z12: D2: Why We Win Home page (bottomRight): report chart | AA12: 00OgK00000EysQfUAJ
A13: R10b | B13: Why We Lose – YTD | G13: Dashboard source: Closed Lost this fiscal year by loss reason. | H13: Summary | I13: Opportunity | J13: All opportunities | K13: All Opportunities | L13: Close Date | M13: Current FY | N13: 1 Jan 2026 – 31 Dec 2026 | O13: 1. Stage equals "Closed Lost" | P13: AND (all conditions) | Q13: Win/Loss Reason | R13: – | S13: Opportunity Name, Account Name, Opportunity Owner, Amount, Win/Loss Details | T13: Sum of Amount, Record Count | U13: – | V13: None | W13: Default | X13: Donut · X: Win/Loss Reason · Y: Sum of Amount · Legend Right | Y13: true / true / true | Z13: D2: Why We Lose | AA13: 00OgK00000EysQgUAJ
... A21: R18 | B21: Average Deal Size & Sales Cycle | G21: Average deal size and age (days) of deals won in the last 365 days. | H21: Summary | I21: Opportunity | J21: All opportunities | K21: All Opportunities | L21: Close Date | M21: All Time | N21: No date limit (custom range left empty) | O21: 1. Stage equals "Closed Won" 2. Close Date equals "LAST_N_DAYS:365" | P21: AND (all conditions) | Q21: Opportunity Owner | R21: – | S21: Opportunity Name, Amount, Age, Created Date, Close Date | T21: Average of Amount, Average of Age, Record Count | U21: – | V21: None | W21: Default | X21: No chart | Y21: true / true / true | Z21: Report only | AA21: 00OgK00000EysQmUAJ

Sheet Report Filters
A1: Report ID | B1: Report name | C1: Filter # | D1: Filter kind | E1: Field | F1: Field API name | G1: Operator | H1: Value | I1: Resolved value (as of 8 Oct 2026) | J1: Filter logic | K1: Meaning
A2: R01 | B2: Revenue Won – YTD by Quarter & Month | C2: S1 | D2: Standard filter: Show Me | E2: Scope | F2: scope | G2: equals | H2: All opportunities | I2: All opportunities | K2: Every user's opportunities are included, not just the viewer's.
A3: R01 | B3: Revenue Won – YTD by Quarter & Month | C3: S2 | D3: Standard filter: Opportunity Status | E3: Opportunity Status | F3: open | G3: equals | H3: All Opportunities | I3: All Opportunities | K3: Open and closed opportunities.
A4: R01 | B4: Revenue Won – YTD by Quarter & Month | C4: S3 | D4: Standard filter: Date range | E4: Close Date | F4: CLOSE_DATE | G4: within | H4: Current FY | I4: 1 Jan 2026 – 31 Dec 2026 | K4: Close Date falls in current fy.
A5: R01 | B5: Revenue Won – YTD by Quarter & Month | C5: 1 | D5: Field filter | E5: Stage | F5: STAGE_NAME | G5: equals | H5: Closed Won | I5: Closed Won | J5: AND | K5: Stage is Closed Won.
A6: R02 | B6: Revenue Won – This Month (MTD) | C6: S1 | D6: Standard filter: Show Me | E6: Scope | F6: scope | G6: equals | H6: All opportunities | I6: All opportunities | K6: Every user's opportunities are included, not just the viewer's.
A7: R02 | B7: Revenue Won – This Month (MTD) | C7: S2 | D7: Standard filter: Opportunity Status | E7: Opportunity Status | F7: open | G7: equals | H7: All Opportunities | I7: All Opportunities | K7: Open and closed opportunities.
A8: R02 | B8: Revenue Won – This Month (MTD) | C8: S3 | D8: Standard filter: Date range | E8: Close Date | F8: CLOSE_DATE | G8: within | H8: Current Calendar Month | I8: 1 Oct 2026 – 31 Oct 2026 | K8: Close Date falls in current calendar month.
A9: R02 | B9: Revenue Won – This Month (MTD) | C9: 1 | D9: Field filter | E9: Stage | F9: STAGE_NAME | G9: equals | H9: Closed Won | I9: Closed Won | J9: AND | K9: Stage is Closed Won.
A10: R03 | B10: Revenue Won – This Quarter (QTD) | C10: S1 | D10: Standard filter: Show Me | E10: Scope | F10: scope | G10: equals | H10: All opportunities | I10: All opportunities | K10: Every user's opportunities are included, not just the viewer's.
A11: R03 | B11: Revenue Won – This Quarter (QTD) | C11: S2 | D11: Standard filter: Opportunity Status | E11: Opportunity Status | F11: open | G11: equals | H11: All Opportunities | I11: All Opportunities | K11: Open and closed opportunities.
A12: R03 | B12: Revenue Won – This Quarter (QTD) | C12: S3 | D12: Standard filter: Date range | E12: Close Date | F12: CLOSE_DATE | G12: within | H12: Current FQ | I12: 1 Oct 2026 – 31 Dec 2026 | K12: Close Date falls in current fq.
A13: R03 | B13: Revenue Won – This Quarter (QTD) | C13: 1 | D13: Field filter | E13: Stage | F13: STAGE_NAME | G13: equals | H13: Closed Won | I13: Closed Won | J13: AND | K13: Stage is Closed Won.
A14: R04 | B14: Revenue Won – This Year vs Last Year | C14: S1 | D14: Standard filter: Show Me | E14: Scope | F14: scope | G14: equals | H14: All opportunities | I14: All opportunities | K14: Every user's opportunities are included, not just the viewer's.
A15: R04 | B15: Revenue Won – This Year vs Last Year | C15: S2 | D15: Standard filter: Opportunity Status | E15: Opportunity Status | F15: open | G15: equals | H15: All Opportunities | I15: All Opportunities | K15: Open and closed opportunities.
A16: R04 | B16: Revenue Won – This Year vs Last Year | C16: S3 | D16: Standard filter: Date range | E16: Close Date | F16: CLOSE_DATE | G16: within | H16: Previous FY + Current FY | I16: 1 Jan 2025 – 31 Dec 2026 | K16: Close Date falls in previous fy + current fy.
A17: R04 | B17: Revenue Won – This Year vs Last Year | C17: 1 | D17: Field filter | E17: Stage | F17: STAGE_NAME | G17: equals | H17: Closed Won | I17: Closed Won | J17: AND | K17: Stage is Closed Won.
A18: R05 | B18: Open Pipeline by Stage | C18: S1 | D18: Standard filter: Show Me | E18: Scope | F18: scope | G18: equals | H18: All opportunities | I18: All opportunities | K18: Every user's opportunities are included, not just the viewer's.
A19: R05 | B19: Open Pipeline by Stage | C19: S2 | D19: Standard filter: Opportunity Status | E19: Opportunity Status | F19: open | G19: equals | H19: Open Opportunities | I19: Open Opportunities | K19: Only opportunities that are not closed.
A20: R05 | B20: Open Pipeline by Stage | C20: S3 | D20: Standard filter: Date range | E20: Close Date | F20: CLOSE_DATE | G20: within | H20: All Time | I20: No date limit (custom range left empty) | K20: Close Date falls in all time.
A21: R05 | B21: Open Pipeline by Stage | C21: 1 | D21: Field filter | E21: Stage | F21: STAGE_NAME | G21: not equal to | H21: Deferred,Old / Archived | I21: Deferred,Old / Archived | J21: AND | K21: Stage is not Deferred or Old / Archived.
A22: R06 | B22: Pipeline by Close Quarter (Next 4) | C22: S1 | D22: Standard filter: Show Me | E22: Scope | F22: scope | G22: equals | H22: All opportunities | I22: All opportunities | K22: Every user's opportunities are included, not just the viewer's.
A23: R06 | B23: Pipeline by Close Quarter (Next 4) | C23: S2 | D23: Standard filter: Opportunity Status | E23: Opportunity Status | F23: open | G23: equals | H23: Open Opportunities | I23: Open Opportunities | K23: Only opportunities that are not closed.
A24: R06 | B24: Pipeline by Close Quarter (Next 4) | C24: S3 | D24: Standard filter: Date range | E24: Close Date | F24: CLOSE_DATE | G24: within | H24: Current FQ + Next 3 FQ | I24: 1 Oct 2026 – 30 Sep 2027 | K24: Close Date falls in current fq + next 3 fq.
A25: R06 | B25: Pipeline by Close Quarter (Next 4) | C25: 1 | D25: Field filter | E25: Stage | F25: STAGE_NAME | G25: not equal to | H25: Deferred,Old / Archived | I25: Deferred,Old / Archived | J25: AND | K25: Stage is not Deferred or Old / Archived.
A26: R07 | B26: Pipeline by Salesperson & Stage | C26: S1 | D26: Standard filter: Show Me | E26: Scope | F26: scope | G26: equals | H26: All opportunities | I26: All opportunities | K26: Every user's opportunities are included, not just the viewer's.
A27: R07 | B27: Pipeline by Salesperson & Stage | C27: S2 | D27: Standard filter: Opportunity Status | E27: Opportunity Status | F27: open | G27: equals | H27: Open Opportunities | I27: Open Opportunities | K27: Only opportunities that are not closed.
A28: R07 | B28: Pipeline by Salesperson & Stage | C28: S3 | D28: Standard filter: Date range | E28: Close Date | F28: CLOSE_DATE | G28: within | H28: All Time | I28: No date limit (custom range left empty) | K28: Close Date falls in all time.
A29: R07 | B29: Pipeline by Salesperson & Stage | C29: 1 | D29: Field filter | E29: Stage | F29: STAGE_NAME | G29: not equal to | H29: Deferred,Old / Archived | I29: Deferred,Old / Archived | J29: AND | K29: Stage is not Deferred or Old / Archived.
A30: R08 | B30: Revenue Won by Salesperson – YTD | C30: S1 | D30: Standard filter: Show Me | E30: Scope | F30: scope | G30: equals | H30: All opportunities | I30: All opportunities | K30: Every user's opportunities are included, not just the viewer's.
A31: R08 | B31: Revenue Won by Salesperson – YTD | C31: S2 | D31: Standard filter: Opportunity Status | E31: Opportunity Status | F31: open | G31: equals | H31: All Opportunities | I31: All Opportunities | K31: Open and closed opportunities.
A32: R08 | B32: Revenue Won by Salesperson – YTD | C32: S3 | D32: Standard filter: Date range | E32: Close Date | F32: CLOSE_DATE | G32: within | H32: Current FY | I32: 1 Jan 2026 – 31 Dec 2026 | K32: Close Date falls in current fy.
A33: R08 | B33: Revenue Won by Salesperson – YTD | C33: 1 | D33: Field filter | E33: Stage | F33: STAGE_NAME | G33: equals | H33: Closed Won | I33: Closed Won | J33: AND | K33: Stage is Closed Won.
A34: R09 | B34: Win Rate by Salesperson – YTD | C34: S1 | D34: Standard filter: Show Me | E34: Scope | F34: scope | G34: equals | H34: All opportunities | I34: All opportunities | K34: Every user's opportunities are included, not just the viewer's.
A35: R09 | B35: Win Rate by Salesperson – YTD | C35: S2 | D35: Standard filter: Opportunity Status | E35: Opportunity Status | F35: open | G35: equals | H35: Closed Opportunities | I35: Closed Opportunities | K35: Only Closed Won and Closed Lost opportunities.
A36: R09 | B36: Win Rate by Salesperson – YTD | C36: S3 | D36: Standard filter: Date range | E36: Close Date | F36: CLOSE_DATE | G36: within | H36: Current FY | I36: 1 Jan 2026 – 31 Dec 2026 | K36: Close Date falls in current fy.
A37: R10 | B37: Win-Loss Analysis by Reason – YTD | C37: S1 | D37: Standard filter: Show Me | E37: Scope | F37: scope | G37: equals | H37: All opportunities | I37: All opportunities | K37: Every user's opportunities are included, not just the viewer's.
A38: R10 | B38: Win-Loss Analysis by Reason – YTD | C38: S2 | D38: Standard filter: Opportunity Status | E38: Opportunity Status | F38: open | G38: equals | H38: Closed Opportunities | I38: Closed Opportunities | K38: Only Closed Won and Closed Lost opportunities.
A39: R10 | B39: Win-Loss Analysis by Reason – YTD | C39: S3 | D39: Standard filter: Date range | E39: Close Date | F39: CLOSE_DATE | G39: within | H39: Current FY | I39: 1 Jan 2026 – 31 Dec 2026 | K39: Close Date falls in current fy.
A40: R10a | B40: Why We Win – YTD | C40: S1 | D40: Standard filter: Show Me | E40: Scope | F40: scope | G40: equals | H40: All opportunities | I40: All opportunities | K40: Every user's opportunities are included, not just the viewer's.
...

Sheet Report Fields
A1: Report ID | B1: Report name | C1: Role | D1: Order | E1: Field | F1: Field API name | G1: Aggregate / granularity | H1: Sort
A2: R01 | B2: Revenue Won – YTD by Quarter & Month | C2: Field filter | E2: Stage | F2: STAGE_NAME | G2: equals Closed Won
A3: R01 | B3: Revenue Won – YTD by Quarter & Month | C3: Date filter | E3: Close Date | F3: CLOSE_DATE | G3: Current FY
A4: R01 | B4: Revenue Won – YTD by Quarter & Month | C4: Group rows by | D4: 1 | E4: Close Date | F4: CLOSE_DATE | G4: Fiscal Quarter | H4: Asc
A5: R01 | B5: Revenue Won – YTD by Quarter & Month | C5: Group rows by | D5: 2 | E5: Close Month | F5: CLOSE_MONTH | G5: Calendar Month | H5: Asc
A6: R01 | B6: Revenue Won – YTD by Quarter & Month | C6: Detail column | D6: 1 | E6: Opportunity Name | F6: OPPORTUNITY_NAME
A7: R01 | B7: Revenue Won – YTD by Quarter & Month | C7: Detail column | D7: 2 | E7: Account Name | F7: ACCOUNT_NAME
A8: R01 | B8: Revenue Won – YTD by Quarter & Month | C8: Detail column | D8: 3 | E8: Opportunity Owner | F8: FULL_NAME
A9: R01 | B9: Revenue Won – YTD by Quarter & Month | C9: Detail column | D9: 4 | E9: Type | F9: TYPE
A10: R01 | B10: Revenue Won – YTD by Quarter & Month | C10: Detail column | D10: 5 | E10: Amount | F10: AMOUNT | G10: Sum
A11: R01 | B11: Revenue Won – YTD by Quarter & Month | C11: Chart X-axis | E11: Close Date | F11: CLOSE_DATE | G11: VerticalColumn
A12: R02 | B12: Revenue Won – This Month (MTD) | C12: Field filter | E12: Stage | F12: STAGE_NAME | G12: equals Closed Won
A13: R02 | B13: Revenue Won – This Month (MTD) | C13: Date filter | E13: Close Date | F13: CLOSE_DATE | G13: Current Calendar Month
A14: R02 | B14: Revenue Won – This Month (MTD) | C14: Group rows by | D14: 1 | E14: Opportunity Owner | F14: FULL_NAME | H14: Asc
A15: R02 | B15: Revenue Won – This Month (MTD) | C15: Detail column | D15: 1 | E15: Opportunity Name | F15: OPPORTUNITY_NAME
A16: R02 | B16: Revenue Won – This Month (MTD) | C16: Detail column | D16: 2 | E16: Account Name | F16: ACCOUNT_NAME
A17: R02 | B17: Revenue Won – This Month (MTD) | C17: Detail column | D17: 3 | E17: Amount | F17: AMOUNT | G17: Sum
A18: R02 | B18: Revenue Won – This Month (MTD) | C18: Detail column | D18: 4 | E18: Close Date | F18: CLOSE_DATE
A19: R03 | B19: Revenue Won – This Quarter (QTD) | C19: Field filter | E19: Stage | F19: STAGE_NAME | G19: equals Closed Won
A20: R03 | B20: Revenue Won – This Quarter (QTD) | C20: Date filter | E20: Close Date | F20: CLOSE_DATE | G20: Current FQ
A21: R03 | B21: Revenue Won – This Quarter (QTD) | C21: Group rows by | D21: 1 | E21: Opportunity Owner | F21: FULL_NAME | H21: Asc
A22: R03 | B22: Revenue Won – This Quarter (QTD) | C22: Detail column | D22: 1 | E22: Opportunity Name | F22: OPPORTUNITY_NAME
A23: R03 | B23: Revenue Won – This Quarter (QTD) | C23: Detail column | D23: 2 | E23: Account Name | F23: ACCOUNT_NAME
A24: R03 | B24: Revenue Won – This Quarter (QTD) | C24: Detail column | D24: 3 | E24: Amount | F24: AMOUNT | G24: Sum
A25: R03 | B25: Revenue Won – This Quarter (QTD) | C25: Detail column | D25: 4 | E25: Close Date | F25: CLOSE_DATE
A26: R04 | B26: Revenue Won – This Year vs Last Year | C26: Field filter | E26: Stage | F26: STAGE_NAME | G26: equals Closed Won
A27: R04 | B27: Revenue Won – This Year vs Last Year | C27: Date filter | E27: Close Date | F27: CLOSE_DATE | G27: Previous FY + Current FY
A28: R04 | B28: Revenue Won – This Year vs Last Year | C28: Group rows by | D28: 1 | E28: Close Quarter | F28: Opportunity.Close_Quarter__c | H28: Asc
A29: R04 | B29: Revenue Won – This Year vs Last Year | C29: Group columns by | D29: 1 | E29: Close Date | F29: CLOSE_DATE | G29: Fiscal Year | H29: Asc
A30: R04 | B30: Revenue Won – This Year vs Last Year | C30: Detail column | D30: 1 | E30: Amount | F30: AMOUNT | G30: Sum
A31: R04 | B31: Revenue Won – This Year vs Last Year | C31: Chart X-axis | E31: Close Quarter | F31: Opportunity.Close_Quarter__c | G31: VerticalColumnGrouped
A32: R04 | B32: Revenue Won – This Year vs Last Year | C32: Chart series | E32: Close Date | F32: CLOSE_DATE | G32: VerticalColumnGrouped
A33: R05 | B33: Open Pipeline by Stage | C33: Field filter | E33: Stage | F33: STAGE_NAME | G33: not equal to Deferred,Old / Archived
A34: R05 | B34: Open Pipeline by Stage | C34: Date filter | E34: Close Date | F34: CLOSE_DATE | G34: All Time
A35: R05 | B35: Open Pipeline by Stage | C35: Group rows by | D35: 1 | E35: Stage | F35: STAGE_NAME | H35: Asc
A36: R05 | B36: Open Pipeline by Stage | C36: Detail column | D36: 1 | E36: Opportunity Name | F36: OPPORTUNITY_NAME
A37: R05 | B37: Open Pipeline by Stage | C37: Detail column | D37: 2 | E37: Account Name | F37: ACCOUNT_NAME
A38: R05 | B38: Open Pipeline by Stage | C38: Detail column | D38: 3 | E38: Opportunity Owner | F38: FULL_NAME
A39: R05 | B39: Open Pipeline by Stage | C39: Detail column | D39: 4 | E39: Amount | F39: AMOUNT | G39: Sum
A40: R05 | B40: Open Pipeline by Stage | C40: Detail column | D40: 5 | E40: Probability (%) | F40: PROBABILITY
...

Sheet Field Usage Matrix
A1: Field | B1: Field API name | C1: R01 | D1: R02 | E1: R03 | F1: R04 | G1: R05 | H1: R06 | I1: R07 | J1: R08 | K1: R09 | L1: R10 | M1: R10a | N1: R10b | O1: R11 | P1: R12 | Q1: R13 | R1: R14 | S1: R15 | T1: R16 | U1: R17 | V1: R18 | W1: Reports using it
A2: Account Name | B2: ACCOUNT_NAME | C2: C | D2: C | E2: C | G2: C | J2: C | L2: C | M2: C | N2: C | O2: C | Q2: C | S2: C | U2: C | W2: =COUNTIF(C2:V2,"?*") -> 12
A3: Account: Billing Country | B3: ADDRESS1_COUNTRY_CODE | T3: GC | W3: =COUNTIF(C3:V3,"?*") -> 1
A4: Account: Industry | B4: INDUSTRY | T4: GR | W4: =COUNTIF(C4:V4,"?*") -> 1
A5: Account: Segment | B5: Account.Segment__c | T5: C | W5: =COUNTIF(C5:V5,"?*") -> 1
A6: Age | B6: AGE | V6: CΣ | W6: =COUNTIF(C6:V6,"?*") -> 1
A7: Amount | B7: AMOUNT | C7: CΣ | D7: CΣ | E7: CΣ | F7: CΣ | G7: CΣ | H7: CΣ | I7: CΣ | J7: CΣ | K7: CΣ | L7: CΣ | M7: CΣ | N7: CΣ | O7: CΣ | P7: CΣ S | Q7: CΣ | R7: CΣ | S7: CΣ | T7: CΣ | U7: CΣ | V7: CΣ | W7: =COUNTIF(C7:V7,"?*") -> 20
A8: Close Date | B8: CLOSE_DATE | C8: D GR | D8: D C | E8: D C | F8: D GC | G8: D C | H8: D GR | I8: D | J8: D C | K8: D | L8: D | M8: D | N8: D | O8: D C S | P8: F D C | Q8: D C | R8: D | S8: D | T8: D | V8: F D C | W8: =COUNTIF(C8:V8,"?*") -> 19
A9: Close Month | B9: CLOSE_MONTH | C9: GR | W9: =COUNTIF(C9:V9,"?*") -> 1
A10: Close Quarter | B10: Opportunity.Close_Quarter__c | F10: GR | W10: =COUNTIF(C10:V10,"?*") -> 1
A11: Closed | B11: CLOSED | K11: C | W11: =COUNTIF(C11:V11,"?*") -> 1
A12: Created Date | B12: CREATED_DATE | V12: C | W12: =COUNTIF(C12:V12,"?*") -> 1
A13: Deferred Date | B13: Opportunity.Deferred_Date__c | Q13: C | W13: =COUNTIF(C13:V13,"?*") -> 1
A14: Expected Revenue | B14: EXP_AMOUNT | G14: CΣ | W14: =COUNTIF(C14:V14,"?*") -> 1
A15: Forecast Category | B15: FORECAST_CATEGORY | H15: GC | W15: =COUNTIF(C15:V15,"?*") -> 1
A16: Last Activity | B16: LAST_ACTIVITY | P16: F C | W16: =COUNTIF(C16:V16,"?*") -> 1
A17: Last Modified Date | B17: LAST_UPDATE | P17: C | W17: =COUNTIF(C17:V17,"?*") -> 1
A18: Lead Source | B18: LEAD_SOURCE | S18: GR | W18: =COUNTIF(C18:V18,"?*") -> 1
A19: Next Step | B19: NEXT_STEP | G19: C | O19: C | W19: =COUNTIF(C19:V19,"?*") -> 2
A20: Opportunity Name | B20: OPPORTUNITY_NAME | C20: C | D20: C | E20: C | G20: C | J20: C | K20: C | L20: C | M20: C | N20: C | O20: C | P20: C | Q20: C | S20: C | U20: C | V20: C | W20: =COUNTIF(C20:V20,"?*") -> 15
A21: Opportunity Owner | B21: FULL_NAME | C21: C | D21: GR | E21: GR | G21: C | I21: GR | J21: GR | K21: GR | L21: C | M21: C | N21: C | O21: C | P21: C | Q21: GR | U21: C | V21: GR | W21: =COUNTIF(C21:V21,"?*") -> 15
A22: Primary Campaign Source | B22: CAMPAIGN_SOURCE | S22: GR | W22: =COUNTIF(C22:V22,"?*") -> 1
A23: Probability (%) | B23: PROBABILITY | G23: C | W23: =COUNTIF(C23:V23,"?*") -> 1
A24: Proposal Submission Date | B24: Opportunity.Proposal_Submission_Date__c | U24: D C S | W24: =COUNTIF(C24:V24,"?*") -> 1
A25: Stage | B25: STAGE_NAME | C25: F | D25: F | E25: F | F25: F | G25: F GR | H25: F | I25: F GC | J25: F | K25: C | L25: GR | M25: F | N25: F | O25: F C | P25: F C | Q25: F | R25: F | S25: F | T25: F | U25: C | V25: F | W25: =COUNTIF(C25:V25,"?*") -> 20
A26: Type | B26: TYPE | C26: C | R26: GR | W26: =COUNTIF(C26:V26,"?*") -> 2
A27: Win Rate % (custom summary formula) | B27: FORMULA1 | K27: SF | W27: =COUNTIF(C27:V27,"?*") -> 1
A28: Win/Loss Details | B28: Opportunity.Win_Loss_Details__c | L28: C | M28: C | N28: C | Q28: C | W28: =COUNTIF(C28:V28,"?*") -> 4
A29: Win/Loss Reason | B29: Opportunity.Win_Loss_Reason__c | L29: GR | M29: GR | N29: GR | W29: =COUNTIF(C29:V29,"?*") -> 3
A30: Won | B30: WON | K30: C | R30: GC | W30: =COUNTIF(C30:V30,"?*") -> 2
A32: Legend | B32: F = field filter · D = date-range filter · GR = group rows · GC = group columns · C = detail column · CΣ = column with summary · SF = custom summary formula · S = report sort

Sheet Dashboards
A1: Dashboard ID | B1: Title | C1: API name | D1: Folder | E1: Description | F1: Dashboard type | G1: Running user (View as) | H1: Grid columns | I1: Row height (px) | J1: Components | K1: Theme / palette | L1: Dashboard filter | M1: Filter field | N1: Filter options (operator: equals) | O1: Shown on Home page
A2: D1 | B2: ABA Management – Revenue & Pipeline | C2: ABA_Management_Revenue_Pipeline | D2: ABA Management Dashboards | E2: D1: revenue won (MTD/QTD/YTD), year-on-year trend, pipeline and deals to push now. | F2: Run as a specified user | G2: suraj.od.885d11d47e1b@agentforce.com | H2: 12 | I2: 36 | J2: 9 | K2: light / unity | L2: Opportunity Owner | M2: Opportunity Owner (FULL_NAME) | N2: All, Mohammed Alburayh, Suraj OD, Venkatesh Rethinasamy | O2: Yes – top region
A3: D1 | B3: ABA Management – Revenue & Pipeline | C3: ABA_Management_Revenue_Pipeline | D3: ABA Management Dashboards | F3: Run as a specified user | G3: suraj.od.885d11d47e1b@agentforce.com | H3: 12 | I3: 36 | J3: 9 | K3: light / unity | L3: Account Industry | M3: Account: Industry (INDUSTRY) | N3: All, Agriculture, Banking, Construction, Education, Energy, Food & Beverage, Healthcare, Manufacturing, Oil & Gas, Retail, Telecommunications, Transportation | O3: Yes – top region
A4: D2 | B4: ABA Sales Performance & Win-Loss | C4: ABA_Sales_Performance_Win_Loss | D4: ABA Management Dashboards | E4: D2: salesperson leaderboard, pipeline coverage, win rate, win/loss reasons, revenue mix and hygiene. | F4: Run as a specified user | G4: suraj.od.885d11d47e1b@agentforce.com | H4: 12 | I4: 36 | J4: 9 | K4: light / unity | L4: Opportunity Owner | M4: Opportunity Owner (FULL_NAME) | N4: All, Mohammed Alburayh, Suraj OD, Venkatesh Rethinasamy | O4: Yes – top region
A5: D2 | B5: ABA Sales Performance & Win-Loss | C5: ABA_Sales_Performance_Win_Loss | D5: ABA Management Dashboards | F5: Run as a specified user | G5: suraj.od.885d11d47e1b@agentforce.com | H5: 12 | I5: 36 | J5: 9 | K5: light / unity | L5: Account Industry | M5: Account: Industry (INDUSTRY) | N5: All, Agriculture, Banking, Construction, Education, Energy, Food & Beverage, Healthcare, Manufacturing, Oil & Gas, Retail, Telecommunications, Transportation | O5: Yes – top region

Sheet Dashboard Components
A1: Dashboard ID | B1: Dashboard | C1: Component # | D1: Header | E1: Component type | F1: Grid row | G1: Grid column | H1: Row span | I1: Column span | J1: Source report ID | K1: Source report | L1: Source report filters | M1: Measure | N1: Groupings (X-axis → series) | O1: Sort | P1: Legend / labels | Q1: Gauge or metric bands | R1: Table columns | S1: Table sort | T1: Responds to dashboard filters | U1: Drill-down | V1: Current value (formula)
A2: D1 | B2: ABA Management – Revenue & Pipeline | C2: 1 | D2: Revenue Won – MTD | E2: Metric | F2: 0 | G2: 0 | H2: 4 | I2: 2 | J2: R02 | K2: Revenue Won – This Month (MTD) | L2: All Opportunities Close Date = Current Calendar Month Stage equals "Closed Won" | M2: Sum of Amount | N2: – | O2: – | P2: label 'Month to date' | Q2: Red below 1,000,000, amber to 1,500,000, green above | R2: – | S2: – | T2: Opportunity Owner, Account: Industry | U2: Off (opens report via View Report) | V2: ='Report Results'!D3 -> 2750000
A3: D1 | B3: ABA Management – Revenue & Pipeline | C3: 2 | D3: Revenue Won – QTD vs Target | E3: Gauge | F3: 0 | G3: 2 | H3: 4 | I3: 3 | J3: R03 | K3: Revenue Won – This Quarter (QTD) | L3: All Opportunities Close Date = Current FQ Stage equals "Closed Won" | M3: Sum of Amount | N3: – | O3: – | P3: percent false | Q3: 0 – 3,000,000 red · 3,000,000 – 4,500,000 amber · 4,500,000 – 5,000,000 green (target 5,000,000) | R3: – | S3: – | T3: Opportunity Owner, Account: Industry | U3: Off (opens report via View Report) | V3: ='Report Results'!D4 -> 2750000
A4: D1 | B4: ABA Management – Revenue & Pipeline | C4: 3 | D4: Revenue Won – YTD | E4: Metric | F4: 0 | G4: 5 | H4: 4 | I4: 3 | J4: R01 | K4: Revenue Won – YTD by Quarter & Month | L4: All Opportunities Close Date = Current FY Stage equals "Closed Won" | M4: Sum of Amount | N4: – | O4: – | P4: label 'Year to date' | Q4: Single neutral colour (no target) | R4: – | S4: – | T4: Opportunity Owner, Account: Industry | U4: Off (opens report via View Report) | V4: ='Report Results'!D2 -> 8900000
A5: D1 | B5: ABA Management – Revenue & Pipeline | C5: 4 | D5: Open Pipeline Value | E5: Metric | F5: 0 | G5: 8 | H5: 4 | I5: 2 | J5: R05 | K5: Open Pipeline by Stage | L5: Open Opportunities Close Date = All Time Stage not equal to "Deferred,Old / Archived" | M5: Sum of Amount | N5: – | O5: – | P5: label 'Active pipeline' | Q5: Single neutral colour (no target) | R5: – | S5: – | T5: Opportunity Owner, Account: Industry | U5: Off (opens report via View Report) | V5: ='Report Results'!D6 -> 31421000
A6: D1 | B6: ABA Management – Revenue & Pipeline | C6: 5 | D6: Win Rate YTD | E6: Metric | F6: 0 | G6: 10 | H6: 4 | I6: 2 | J6: R09 | K6: Win Rate by Salesperson – YTD | L6: Closed Opportunities Close Date = Current FY | M6: Win Rate % (custom summary formula) | N6: – | O6: – | P6: label 'Won / closed' | Q6: Single neutral colour (no target) | R6: – | S6: – | T6: Opportunity Owner, Account: Industry | U6: Off (opens report via View Report) | V6: ='Report Results'!H10 -> 0.6
A7: D1 | B7: ABA Management – Revenue & Pipeline | C7: 6 | D7: Revenue by Quarter – This Year vs Last Year | E7: ColumnGrouped | F7: 4 | G7: 0 | H7: 8 | I7: 6 | J7: R04 | K7: Revenue Won – This Year vs Last Year | L7: All Opportunities Close Date = Previous FY + Current FY Stage equals "Closed Won" | M7: Sum of Amount | N7: Close Quarter → Close Date | O7: RowLabelAscending | P7: legend Bottom, values true, total false, percent false | Q7: – | R7: – | S7: – | T7: Opportunity Owner, Account: Industry | U7: Off (opens report via View Report) | V7: ='Report Results'!D5 -> 16170000
A8: D1 | B8: ABA Management – Revenue & Pipeline | C8: 7 | D8: Pipeline by Stage | E8: Funnel | F8: 4 | G8: 6 | H8: 8 | I8: 6 | J8: R05 | K8: Open Pipeline by Stage | L8: Open Opportunities Close Date = All Time Stage not equal to "Deferred,Old / Archived" | M8: Sum of Amount | N8: Stage | O8: RowLabelAscending | P8: legend Right, values true, total false, percent false | Q8: – | R8: – | S8: – | T8: Opportunity Owner, Account: Industry | U8: Off (opens report via View Report) | V8: ='Report Results'!D6 -> 31421000
A9: D1 | B9: ABA Management – Revenue & Pipeline | C9: 8 | D9: Pipeline by Close Quarter | E9: ColumnStacked | F9: 12 | G9: 0 | H9: 8 | I9: 6 | J9: R06 | K9: Pipeline by Close Quarter (Next 4) | L9: Open Opportunities Close Date = Current FQ + Next 3 FQ Stage not equal to "Deferred,Old / Archived" | M9: Sum of Amount | N9: Close Date → Forecast Category | O9: RowLabelAscending | P9: legend Bottom, values true, total false, percent false | Q9: – | R9: – | S9: – | T9: Opportunity Owner, Account: Industry | U9: Off (opens report via View Report) | V9: ='Report Results'!D7 -> 30271000
A10: D1 | B10: ABA Management – Revenue & Pipeline | C10: 9 | D10: Top Deals Closing in 30 Days | E10: FlexTable | F10: 12 | G10: 6 | H10: 8 | I10: 6 | J10: R11 | K10: Closing in Next 30 Days | L10: Open Opportunities Close Date = Next 30 Days Stage equals "Proposal Submitted,Negotiation,Verbal Award" | M10: Table columns (see right) | N10: – | O10: – | P10: – | Q10: – | R10: Opportunity Name (detail), Account Name (detail), Opportunity Owner (detail), Stage (detail), Amount (detail), Close Date (detail) | S10: Close Date ascending | T10: Opportunity Owner, Account: Industry | U10: Off (opens report via View Report) | V10: ='Report Results'!C14&" rows" -> 3 rows
A11: D2 | B11: ABA Sales Performance & Win-Loss | C11: 1 | D11: Revenue Won by Salesperson | E11: Bar | F11: 0 | G11: 0 | H11: 8 | I11: 4 | J11: R08 | K11: Revenue Won by Salesperson – YTD | L11: All Opportunities Close Date = Current FY Stage equals "Closed Won" | M11: Sum of Amount | N11: Opportunity Owner | O11: RowValueDescending | P11: legend Bottom, values true, total false, percent false | Q11: – | R11: – | S11: – | T11: Opportunity Owner, Account: Industry | U11: Off (opens report via View Report) | V11: ='Report Results'!D9 -> 8900000
A12: D2 | B12: ABA Sales Performance & Win-Loss | C12: 2 | D12: Pipeline by Salesperson & Stage | E12: BarStacked | F12: 0 | G12: 4 | H12: 8 | I12: 4 | J12: R07 | K12: Pipeline by Salesperson & Stage | L12: Open Opportunities Close Date = All Time Stage not equal to "Deferred,Old / Archived" | M12: Sum of Amount | N12: Opportunity Owner → Stage | O12: RowLabelAscending | P12: legend Bottom, values true, total false, percent false | Q12: – | R12: – | S12: – | T12: Opportunity Owner, Account: Industry | U12: Off (opens report via View Report) | V12: ='Report Results'!D8 -> 31421000
A13: D2 | B13: ABA Sales Performance & Win-Loss | C13: 3 | D13: Win Rate by Salesperson | E13: FlexTable | F13: 0 | G13: 8 | H13: 8 | I13: 4 | J13: R09 | K13: Win Rate by Salesperson – YTD | L13: Closed Opportunities Close Date = Current FY | M13: Table columns (see right) | N13: – | O13: – | P13: – | Q13: – | R13: Opportunity Owner (grouping), Win Rate % (custom summary formula) (aggregate), Record Count (aggregate) | S13: Win Rate % (custom summary formula) descending | T13: Opportunity Owner, Account: Industry | U13: Off (opens report via View Report) | V13: ='Report Results'!C10&" rows" -> 15 rows
A14: D2 | B14: ABA Sales Performance & Win-Loss | C14: 4 | D14: Why We Win | E14: Donut | F14: 8 | G14: 0 | H14: 8 | I14: 4 | J14: R10a | K14: Why We Win – YTD | L14: All Opportunities Close Date = Current FY Stage equals "Closed Won" | M14: Sum of Amount | N14: Win/Loss Reason | O14: RowLabelAscending | P14: legend Right, values true, total true, percent false | Q14: – | R14: – | S14: – | T14: Opportunity Owner, Account: Industry | U14: Off (opens report via View Report) | V14: ='Report Results'!D12 -> 8900000
A15: D2 | B15: ABA Sales Performance & Win-Loss | C15: 5 | D15: Why We Lose | E15: Donut | F15: 8 | G15: 4 | H15: 8 | I15: 4 | J15: R10b | K15: Why We Lose – YTD | L15: All Opportunities Close Date = Current FY Stage equals "Closed Lost" | M15: Sum of Amount | N15: Win/Loss Reason | O15: RowLabelAscending | P15: legend Right, values true, total true, percent false | Q15: – | R15: – | S15: – | T15: Opportunity Owner, Account: Industry | U15: Off (opens report via View Report) | V15: ='Report Results'!D13 -> 5820000
A16: D2 | B16: ABA Sales Performance & Win-Loss | C16: 6 | D16: Revenue by Type (New vs Existing) | E16: Donut | F16: 8 | G16: 8 | H16: 8 | I16: 4 | J16: R14 | K16: Revenue & Pipeline by Type | L16: All Opportunities Close Date = Current FY Stage not equal to "Closed Lost,Deferred,Old / Archived" | M16: Sum of Amount | N16: Type | O16: RowLabelAscending | P16: legend Right, values true, total true, percent false | Q16: – | R16: – | S16: – | T16: Opportunity Owner, Account: Industry | U16: Off (opens report via View Report) | V16: ='Report Results'!D17 -> 29821000
A17: D2 | B17: ABA Sales Performance & Win-Loss | C17: 7 | D17: Revenue by Lead Source | E17: Bar | F17: 16 | G17: 0 | H17: 8 | I17: 4 | J17: R15 | K17: Revenue by Lead Source & Campaign | L17: All Opportunities Close Date = Current FY Stage equals "Closed Won" | M17: Sum of Amount | N17: Lead Source | O17: RowValueDescending | P17: legend Bottom, values true, total false, percent false | Q17: – | R17: – | S17: – | T17: Opportunity Owner, Account: Industry | U17: Off (opens report via View Report) | V17: ='Report Results'!D18 -> 8900000
A18: D2 | B18: ABA Sales Performance & Win-Loss | C18: 8 | D18: Deferred Value | E18: Metric | F18: 16 | G18: 4 | H18: 8 | I18: 4 | J18: R13 | K18: Deferred Opportunities | L18: All Opportunities Close Date = All Time Stage equals "Deferred" | M18: Sum of Amount | N18: – | O18: – | P18: label 'Revenue on hold' | Q18: Single neutral colour (no target) | R18: – | S18: – | T18: Opportunity Owner, Account: Industry | U18: Off (opens report via View Report) | V18: ='Report Results'!D16 -> 11500000
A19: D2 | B19: ABA Sales Performance & Win-Loss | C19: 9 | D19: Overdue & Stale Deals | E19: FlexTable | F19: 16 | G19: 8 | H19: 8 | I19: 4 | J19: R12 | K19: Overdue & Stale Opportunities | L19: Open Opportunities Close Date = All Time Stage not equal to "Deferred,Old / Archived" Close Date less than "TODAY" Last Activity less than "LAST_N_DAYS:30" | M19: Table columns (see right) | N19: – | O19: – | P19: – | Q19: – | R19: Opportunity Name (detail), Opportunity Owner (detail), Stage (detail), Amount (detail), Close Date (detail) | S19: Amount descending | T19: Opportunity Owner, Account: Industry | U19: Off (opens report via View Report) | V19: ='Report Results'!C15&" rows" -> 2 rows

Sheet Home Page
A1: Lightning page | B1: Template | C1: Assigned to | D1: Region | E1: Position | F1: Component | G1: Shows | H1: Settings
A2: ABA Sales Home Page (ABA_Sales_Home_Page) | B2: home:desktopTemplate | C2: Sales app (standard__LightningSales), desktop Home tab | D2: top | E2: 1 | F2: desktopDashboards:embeddedDashboard | G2: Embedded dashboard: D1 – ABA Management – Revenue & Pipeline | H2: Height 900 px; hide on error false
A3: ABA Sales Home Page (ABA_Sales_Home_Page) | B3: home:desktopTemplate | C3: Sales app (standard__LightningSales), desktop Home tab | D3: top | E3: 2 | F3: desktopDashboards:embeddedDashboard | G3: Embedded dashboard: D2 – ABA Sales Performance & Win-Loss | H3: Height 1050 px; hide on error false
A4: ABA Sales Home Page (ABA_Sales_Home_Page) | B4: home:desktopTemplate | C4: Sales app (standard__LightningSales), desktop Home tab | D4: bottomLeft | E4: 1 | F4: flexipage:reportChart | G4: Report chart: R05 Open Pipeline by Stage | H4: Label 'Open Pipeline by Stage'; cache 1440 min; refresh button true
A5: ABA Sales Home Page (ABA_Sales_Home_Page) | B5: home:desktopTemplate | C5: Sales app (standard__LightningSales), desktop Home tab | D5: bottomRight | E5: 1 | F5: flexipage:reportChart | G5: Report chart: R10a Why We Win – YTD | H5: Label 'Why We Win – YTD'; cache 1440 min; refresh button true
A6: ABA Sales Home Page (ABA_Sales_Home_Page) | B6: home:desktopTemplate | C6: Sales app (standard__LightningSales), desktop Home tab | D6: sidebar | E6: 1 | F6: flexipage:reportChart | G6: Report chart: R08 Revenue Won by Salesperson – YTD | H6: Label 'Revenue Won by Salesperson – YTD'; cache 1440 min; refresh button true
A7: ABA Sales Home Page (ABA_Sales_Home_Page) | B7: home:desktopTemplate | C7: Sales app (standard__LightningSales), desktop Home tab | D7: sidebar | E7: 2 | F7: flexipage:reportChart | G7: Report chart: R01 Revenue Won – YTD by Quarter & Month | H7: Label 'Revenue Won – YTD'; cache 1440 min; refresh button true

Sheet Opportunity Data
A1: Opportunity ID | B1: Opportunity Name | C1: Account Name | D1: Account: Industry | E1: Account: Billing Country | F1: Account: Segment | G1: Opportunity Owner | H1: Stage | I1: Closed | J1: Won | K1: Probability (%) | L1: Amount | M1: Expected Revenue | N1: Close Date | O1: Close Quarter | P1: Fiscal Year | Q1: Forecast Category | R1: Type | S1: Lead Source | T1: Primary Campaign Source | U1: Offering | V1: Proposal Submission Date | W1: Win/Loss Reason | X1: Win/Loss Details | Y1: Deferred Date | Z1: Next Step | AA1: Last Activity | AB1: Created Date | AC1: Age (days) | AD1: Source of record | AE1: In R01 | AF1: In R02 | AG1: In R03 | AH1: In R04 | AI1: In R05 | AJ1: In R06 | AK1: In R07 | AL1: In R08 | AM1: In R09 | AN1: In R10 | AO1: In R10a | AP1: In R10b | AQ1: In R11 | AR1: In R12 | AS1: In R13 | AT1: In R14 | AU1: In R15 | AV1: In R16 | AW1: In R17 | AX1: In R18
A2: 006gK00000Po2EjQAJ | B2: Desert Bloom Foods – SAP SuccessFactors 2025 | C2: Desert Bloom Foods | D2: Food & Beverage | E2: Saudi Arabia | F2: SME | G2: Suraj OD | H2: Closed Won | I2: 1 | J2: 1 | K2: 1 | L2: 900000 | M2: =L2*K2 -> 900000 | N2: 45711 | O2: Q1 | P2: 2025 | Q2: Closed | R2: Existing Customer – New Opportunity | S2: Web | U2: SAP SuccessFactors | V2: 45680 | W2: Partner (SAP) Influence | X2: Won: partner (sap) influence | AB2: 45650 | AC2: =IF(I2=1,N2-AB2,Overview!$B$5-AB2) -> 61 | AD2: ABA sample CSV | AE2: 0 | AF2: 0 | AG2: 0 | AH2: 1 | AI2: 0 | AJ2: 0 | AK2: 0 | AL2: 0 | AM2: 0 | AN2: 0 | AO2: 0 | AP2: 0 | AQ2: 0 | AR2: 0 | AS2: 0 | AT2: 0 | AU2: 0 | AV2: 0 | AW2: 0 | AX2: 0
A3: 006gK00000Po2EoQAJ | B3: Qassim Agri Ventures – SAP S/4HANA 2025 | C3: Qassim Agri Ventures | D3: Agriculture | E3: Saudi Arabia | F3: SME | G3: Suraj OD | H3: Closed Lost | I3: 1 | J3: 0 | K3: 0 | L3: 2200000 | M3: =L3*K3 -> 0 | N3: 45723 | O3: Q1 | P3: 2025 | Q3: Omitted | R3: Existing Customer – Support | S3: SAP Leads | U3: SAP S/4HANA | V3: 45664 | W3: Budget Cut / No Decision | X3: Lost: budget cut / no decision | AB3: 45599 | AC3: =IF(I3=1,N3-AB3,Overview!$B$5-AB3) -> 124 | AD3: ABA sample CSV | AE3: 0 | AF3: 0 | AG3: 0 | AH3: 0 | AI3: 0 | AJ3: 0 | AK3: 0 | AL3: 0 | AM3: 0 | AN3: 0 | AO3: 0 | AP3: 0 | AQ3: 0 | AR3: 0 | AS3: 0 | AT3: 0 | AU3: 0 | AV3: 0 | AW3: 0 | AX3: 0
A4: 006gK00000Po2F0QAJ | B4: Riyadh Smart Utilities – SAP S/4HANA 2025 | C4: Riyadh Smart Utilities | D4: Energy | E4: Saudi Arabia | F4: Enterprise | G4: Venkatesh Rethinasamy | H4: Closed Lost | I4: 1 | J4: 0 | K4: 0 | L4: 450000 | M4: =L4*K4 -> 0 | N4: 45730 | O4: Q1 | P4: 2025 | Q4: Omitted | R4: Existing Customer – Support | S4: Events & Campaigns | U4: SAP S/4HANA | V4: 45695 | W4: Budget Cut / No Decision | X4: Lost: budget cut / no decision | AB4: 45636 | AC4: =IF(I4=1,N4-AB4,Overview!$B$5-AB4) -> 94 | AD4: ABA sample CSV | AE4: 0 | AF4: 0 | AG4: 0 | AH4: 0 | AI4: 0 | AJ4: 0 | AK4: 0 | AL4: 0 | AM4: 0 | AN4: 0 | AO4: 0 | AP4: 0 | AQ4: 0 | AR4: 0 | AS4: 0 | AT4: 0 | AU4: 0 | AV4: 0 | AW4: 0 | AX4: 0
A5: 006gK00000Po2EkQAJ | B5: Taiba Education Co – SAP SuccessFactors 2025 | C5: Taiba Education Co | D5: Education | E5: Saudi Arabia | F5: Corporate | G5: Venkatesh Rethinasamy | H5: Closed Won | I5: 1 | J5: 1 | K5: 1 | L5: 150000 | M5: =L5*K5 -> 150000 | N5: 45750 | O5: Q2 | P5: 2025 | Q5: Closed | R5: Existing Customer – New Opportunity | S5: SAP Leads | U5: SAP SuccessFactors | V5: 45710 | W5: Price Competitiveness | X5: Won: price competitiveness | AB5: 45673 | AC5: =IF(I5=1,N5-AB5,Overview!$B$5-AB5) -> 77 | AD5: ABA sample CSV | AE5: 0 | AF5: 0 | AG5: 0 | AH5: 1 | AI5: 0 | AJ5: 0 | AK5: 0 | AL5: 0 | AM5: 0 | AN5: 0 | AO5: 0 | AP5: 0 | AQ5: 0 | AR5: 0 | AS5: 0 | AT5: 0 | AU5: 0 | AV5: 0 | AW5: 0 | AX5: 0
A6: 006gK00000Po2EyQAJ | B6: Emirates Facility Mgmt – SAP Support (AMS) 2025 | C6: Emirates Facility Mgmt | D6: Construction | E6: United Arab Emirates | F6: Corporate | G6: Venkatesh Rethinasamy | H6: Closed Won | I6: 1 | J6: 1 | K6: 1 | L6: 150000 | M6: =L6*K6 -> 150000 | N6: 45811 | O6: Q2 | P6: 2025 | Q6: Closed | R6: Existing Customer – New Opportunity | S6: Events & Campaigns | U6: SAP Support (AMS) | V6: 45766 | W6: Customer Relationship / Incumbent | X6: Won: customer relationship / incumbent | AB6: 45721 | AC6: =IF(I6=1,N6-AB6,Overview!$B$5-AB6) -> 90 | AD6: ABA sample CSV | AE6: 0 | AF6: 0 | AG6: 0 | AH6: 1 | AI6: 0 | AJ6: 0 | AK6: 0 | AL6: 0 | AM6: 0 | AN6: 0 | AO6: 0 | AP6: 0 | AQ6: 0 | AR6: 0 | AS6: 0 | AT6: 0 | AU6: 0 | AV6: 0 | AW6: 0 | AX6: 0
A7: 006gK00000Po2F2QAJ | B7: Al Noor Healthcare – Data & Analytics 2025 | C7: Al Noor Healthcare | D7: Healthcare | E7: Saudi Arabia | F7: Enterprise | G7: Suraj OD | H7: Closed Lost | I7: 1 | J7: 0 | K7: 0 | L7: 900000 | M7: =L7*K7 -> 0 | N7: 45814 | O7: Q2 | P7: 2025 | Q7: Omitted | R7: Net New Names | S7: Web | U7: Data & Analytics | V7: 45766 | W7: Lost to Competitor | X7: Lost: lost to competitor | AB7: 45693 | AC7: =IF(I7=1,N7-AB7,Overview!$B$5-AB7) -> 121 | AD7: ABA sample CSV | AE7: 0 | AF7: 0 | AG7: 0 | AH7: 0 | AI7: 0 | AJ7: 0 | AK7: 0 | AL7: 0 | AM7: 0 | AN7: 0 | AO7: 0 | AP7: 0 | AQ7: 0 | AR7: 0 | AS7: 0 | AT7: 0 | AU7: 0 | AV7: 0 | AW7: 0 | AX7: 0
A8: 006gK00000Po2ExQAJ | B8: Red Sea Logistics – SAP S/4HANA 2025 | C8: Red Sea Logistics | D8: Transportation | E8: Saudi Arabia | F8: Corporate | G8: Suraj OD | H8: Closed Won | I8: 1 | J8: 1 | K8: 1 | L8: 320000 | M8: =L8*K8 -> 320000 | N8: 45816 | O8: Q2 | P8: 2025 | Q8: Closed | R8: Existing Customer – New Opportunity | S8: Phone Inquiry | U8: SAP S/4HANA | V8: 45791 | W8: Technical Solution Fit | X8: Won: technical solution fit | AB8: 45753 | AC8: =IF(I8=1,N8-AB8,Overview!$B$5-AB8) -> 63 | AD8: ABA sample CSV | AE8: 0 | AF8: 0 | AG8: 0 | AH8: 1 | AI8: 0 | AJ8: 0 | AK8: 0 | AL8: 0 | AM8: 0 | AN8: 0 | AO8: 0 | AP8: 0 | AQ8: 0 | AR8: 0 | AS8: 0 | AT8: 0 | AU8: 0 | AV8: 0 | AW8: 0 | AX8: 0
A9: 006gK00000Po2F4QAJ | B9: Emirates Facility Mgmt – Cloud Migration 2025 | C9: Emirates Facility Mgmt | D9: Construction | E9: United Arab Emirates | F9: Corporate | G9: Suraj OD | H9: Closed Won | I9: 1 | J9: 1 | K9: 1 | L9: 3500000 | M9: =L9*K9 -> 3500000 | N9: 45827 | O9: Q2 | P9: 2025 | Q9: Closed | R9: Existing Customer – Upgrade/Upsell | S9: Sales Outreach | U9: Cloud Migration | V9: 45769 | W9: Technical Solution Fit | X9: Won: technical solution fit | AB9: 45727 | AC9: =IF(I9=1,N9-AB9,Overview!$B$5-AB9) -> 100 | AD9: ABA sample CSV | AE9: 0 | AF9: 0 | AG9: 0 | AH9: 1 | AI9: 0 | AJ9: 0 | AK9: 0 | AL9: 0 | AM9: 0 | AN9: 0 | AO9: 0 | AP9: 0 | AQ9: 0 | AR9: 0 | AS9: 0 | AT9: 0 | AU9: 0 | AV9: 0 | AW9: 0 | AX9: 0
A10: 006gK00000Po2EnQAJ | B10: Oasis Manufacturing – SAP Support (AMS) 2025 | C10: Oasis Manufacturing | D10: Manufacturing | E10: Saudi Arabia | F10: SME | G10: Suraj OD | H10: Closed Won | I10: 1 | J10: 1 | K10: 1 | L10: 1500000 | M10: =L10*K10 -> 1500000 | N10: 45847 | O10: Q3 | P10: 2025 | Q10: Closed | R10: Net New Names | S10: Events & Campaigns | U10: SAP Support (AMS) | V10: 45810 | W10: Partner (SAP) Influence | X10: Won: partner (sap) influence | AB10: 45752 | AC10: =IF(I10=1,N10-AB10,Overview!$B$5-AB10) -> 95 | AD10: ABA sample CSV | AE10: 0 | AF10: 0 | AG10: 0 | AH10: 1 | AI10: 0 | AJ10: 0 | AK10: 0 | AL10: 0 | AM10: 0 | AN10: 0 | AO10: 0 | AP10: 0 | AQ10: 0 | AR10: 0 | AS10: 0 | AT10: 0 | AU10: 0 | AV10: 0 | AW10: 0 | AX10: 0
A11: 006gK00000Po2ElQAJ | B11: Gulf Petrochem Services – Data & Analytics 2025 | C11: Gulf Petrochem Services | D11: Oil & Gas | E11: Saudi Arabia | F11: Enterprise | G11: Mohammed Alburayh | H11: Closed Lost | I11: 1 | J11: 0 | K11: 0 | L11: 250000 | M11: =L11*K11 -> 0 | N11: 45890 | O11: Q3 | P11: 2025 | Q11: Omitted | R11: Existing Customer – New Opportunity | S11: SAP Leads | U11: Data & Analytics | V11: 45862 | W11: Scope Cancelled | X11: Lost: scope cancelled | AB11: 45818 | AC11: =IF(I11=1,N11-AB11,Overview!$B$5-AB11) -> 72 | AD11: ABA sample CSV | AE11: 0 | AF11: 0 | AG11: 0 | AH11: 0 | AI11: 0 | AJ11: 0 | AK11: 0 | AL11: 0 | AM11: 0 | AN11: 0 | AO11: 0 | AP11: 0 | AQ11: 0 | AR11: 0 | AS11: 0 | AT11: 0 | AU11: 0 | AV11: 0 | AW11: 0 | AX11: 0
A12: 006gK00000Po2F5QAJ | B12: Taiba Education Co – SAP S/4HANA 2025 | C12: Taiba Education Co | D12: Education | E12: Saudi Arabia | F12: Corporate | G12: Mohammed Alburayh | H12: Closed Lost | I12: 1 | J12: 0 | K12: 0 | L12: 1500000 | M12: =L12*K12 -> 0 | N12: 45967 | O12: Q4 | P12: 2025 | Q12: Omitted | R12: Existing Customer – Support | S12: Phone Inquiry | U12: SAP S/4HANA | V12: 45926 | W12: Pricing / Commercial | X12: Lost: pricing / commercial | AB12: 45877 | AC12: =IF(I12=1,N12-AB12,Overview!$B$5-AB12) -> 90 | AD12: ABA sample CSV | AE12: 0 | AF12: 0 | AG12: 0 | AH12: 0 | AI12: 0 | AJ12: 0 | AK12: 0 | AL12: 0 | AM12: 0 | AN12: 0 | AO12: 0 | AP12: 0 | AQ12: 0 | AR12: 0 | AS12: 0 | AT12: 0 | AU12: 0 | AV12: 0 | AW12: 0 | AX12: 0
A13: 006gK00000Po2EpQAJ | B13: Oasis Manufacturing – Cloud Migration 2025 | C13: Oasis Manufacturing | D13: Manufacturing | E13: Saudi Arabia | F13: SME | G13: Venkatesh Rethinasamy | H13: Closed Won | I13: 1 | J13: 1 | K13: 1 | L13: 750000 | M13: =L13*K13 -> 750000 | N13: 45968 | O13: Q4 | P13: 2025 | Q13: Closed | R13: Existing Customer – New Opportunity | S13: Partner Referral | U13: Cloud Migration | V13: 45928 | W13: Technical Solution Fit | X13: Won: technical solution fit | AB13: 45856 | AC13: =IF(I13=1,N13-AB13,Overview!$B$5-AB13) -> 112 | AD13: ABA sample CSV | AE13: 0 | AF13: 0 | AG13: 0 | AH13: 1 | AI13: 0 | AJ13: 0 | AK13: 0 | AL13: 0 | AM13: 0 | AN13: 0 | AO13: 0 | AP13: 0 | AQ13: 0 | AR13: 0 | AS13: 0 | AT13: 0 | AU13: 0 | AV13: 0 | AW13: 0 | AX13: 1
... A26: 006gK00000Po2EzQAJ | B26: Bahrain Telecom Partners – SAP S/4HANA 2026 | C26: Bahrain Telecom Partners | D26: Telecommunications | E26: Bahrain | F26: Corporate | G26: Venkatesh Rethinasamy | H26: Closed Won | I26: 1 | J26: 1 | K26: 1 | L26: 1200000 | M26: =L26*K26 -> 1200000 | N26: 46234 | O26: Q3 | P26: 2026 | Q26: Closed | R26: Existing Customer – Change Request | S26: Sales Outreach | U26: SAP S/4HANA | V26: 46184 | W26: Delivery Capability & References | X26: Won: delivery capability & references | AB26: 46132 | AC26: =IF(I26=1,N26-AB26,Overview!$B$5-AB26) -> 102 | AD26: ABA sample CSV | AE26: 1 | AF26: 0 | AG26: 0 | AH26: 1 | AI26: 0 | AJ26: 0 | AK26: 0 | AL26: 1 | AM26: 1 | AN26: 1 | AO26: 1 | AP26: 0 | AQ26: 0 | AR26: 0 | AS26: 0 | AT26: 1 | AU26: 1 | AV26: 1 | AW26: 0 | AX26: 1
A27: 006gK00000Po2FOQAZ | B27: Riyadh Smart Utilities – SAP S/4HANA 2026 | C27: Riyadh Smart Utilities | D27: Energy | E27: Saudi Arabia | F27: Enterprise | G27: Suraj OD | H27: Internal Review | I27: 0 | J27: 0 | K27: 0.5 | L27: 900000 | M27: =L27*K27 -> 450000 | N27: 46239 | O27: Q3 | P27: 2026 | Q27: Pipeline | R27: Net New Names | S27: Phone Inquiry | U27: SAP S/4HANA | V27: 46199 | AB27: 46152 | AC27: =IF(I27=1,N27-AB27,Overview!$B$5-AB27) -> 151 | AD27: ABA sample CSV | AE27: 0 | AF27: 0 | AG27: 0 | AH27: 0 | AI27: 1 | AJ27: 0 | AK27: 1 | AL27: 0 | AM27: 0 | AN27: 0 | AO27: 0 | AP27: 0 | AQ27: 0 | AR27: 1 | AS27: 0 | AT27: 1 | AU27: 0 | AV27: 0 | AW27: 0 | AX27: 0
A28: 006gK00000Po2F1QAJ | B28: Gulf Petrochem Services – SAP S/4HANA 2026 | C28: Gulf Petrochem Services | D28: Oil & Gas | E28: Saudi Arabia | F28: Enterprise | G28: Mohammed Alburayh | H28: Closed Won | I28: 1 | J28: 1 | K28: 1 | L28: 150000 | M28: =L28*K28 -> 150000 | N28: 46242 | O28: Q3 | P28: 2026 | Q28: Closed | R28: Net New Names | S28: Web | U28: SAP S/4HANA | V28: 46194 | W28: Price Competitiveness | X28: Won: price competitiveness | AB28: 46128 | AC28: =IF(I28=1,N28-AB28,Overview!$B$5-AB28) -> 114 | AD28: ABA sample CSV | AE28: 1 | AF28: 0 | AG28: 0 | AH28: 1 | AI28: 0 | AJ28: 0 | AK28: 0 | AL28: 1 | AM28: 1 | AN28: 1 | AO28: 1 | AP28: 0 | AQ28: 0 | AR28: 0 | AS28: 0 | AT28: 1 | AU28: 1 | AV28: 1 | AW28: 0 | AX28: 1
A29: 006gK00000Po2FPQAZ | B29: Bahrain Telecom Partners – SAP Support (AMS) 2026 | C29: Bahrain Telecom Partners | D29: Telecommunications | E29: Bahrain | F29: Corporate | G29: Venkatesh Rethinasamy | H29: Verbal Award | I29: 0 | J29: 0 | K29: 0.9 | L29: 250000 | M29: =L29*K29 -> 225000 | N29: 46295 | O29: Q3 | P29: 2026 | Q29: Commit | R29: Existing Customer – Support | S29: Phone Inquiry | U29: SAP Support (AMS) | V29: 46247 | AB29: 46193 | AC29: =IF(I29=1,N29-AB29,Overview!$B$5-AB29) -> 110 | AD29: ABA sample CSV | AE29: 0 | AF29: 0 | AG29: 0 | AH29: 0 | AI29: 1 | AJ29: 0 | AK29: 1 | AL29: 0 | AM29: 0 | AN29: 0 | AO29: 0 | AP29: 0 | AQ29: 0 | AR29: 1 | AS29: 0 | AT29: 1 | AU29: 0 | AV29: 0 | AW29: 0 | AX29: 0
A30: 006gK00000Po2FVQAZ | B30: Najd Retail Group – SAP S/4HANA 2026 | C30: Najd Retail Group | D30: Retail | E30: Saudi Arabia | F30: Corporate | G30: Venkatesh Rethinasamy | H30: Closed Won | I30: 1 | J30: 1 | K30: 1 | L30: 1800000 | M30: =L30*K30 -> 1800000 | N30: 46297 | O30: Q4 | P30: 2026 | Q30: Closed | R30: Existing Customer – New Opportunity | S30: Sales Outreach | U30: SAP S/4HANA | V30: 46267 | W30: Price Competitiveness | X30: Won: price competitiveness | AB30: 46216 | AC30: =IF(I30=1,N30-AB30,Overview!$B$5-AB30) -> 81 | AD30: ABA sample CSV | AE30: 1 | AF30: 1 | AG30: 1 | AH30: 1 | AI30: 0 | AJ30: 0 | AK30: 0 | AL30: 1 | AM30: 1 | AN30: 1 | AO30: 1 | AP30: 0 | AQ30: 0 | AR30: 0 | AS30: 0 | AT30: 1 | AU30: 1 | AV30: 1 | AW30: 0 | AX30: 1
A31: 006gK00000Po2FWQAZ | B31: Al Noor Healthcare – SAP SuccessFactors 2026 | C31: Al Noor Healthcare | D31: Healthcare | E31: Saudi Arabia | F31: Enterprise | G31: Suraj OD | H31: Closed Won | I31: 1 | J31: 1 | K31: 1 | L31: 950000 | M31: =L31*K31 -> 950000 | N31: 46301 | O31: Q4 | P31: 2026 | Q31: Closed | R31: Existing Customer – New Opportunity | S31: Sales Outreach | U31: SAP SuccessFactors | V31: 46271 | W31: Technical Solution Fit | X31: Won: technical solution fit | AB31: 46213 | AC31: =IF(I31=1,N31-AB31,Overview!$B$5-AB31) -> 88 | AD31: ABA sample CSV | AE31: 1 | AF31: 1 | AG31: 1 | AH31: 1 | AI31: 0 | AJ31: 0 | AK31: 0 | AL31: 1 | AM31: 1 | AN31: 1 | AO31: 1 | AP31: 0 | AQ31: 0 | AR31: 0 | AS31: 0 | AT31: 1 | AU31: 1 | AV31: 1 | AW31: 0 | AX31: 1
A32: 006gK00000Po2FYQAZ | B32: Khaleej Finance House – Cloud Migration 2026 | C32: Khaleej Finance House | D32: Banking | E32: United Arab Emirates | F32: Enterprise | G32: Venkatesh Rethinasamy | H32: Verbal Award | I32: 0 | J32: 0 | K32: 0.9 | L32: 1300000 | M32: =L32*K32 -> 1170000 | N32: 46315 | O32: Q4 | P32: 2026 | Q32: Commit | R32: Existing Customer – New Opportunity | S32: Sales Outreach | U32: Cloud Migration | V32: 46285 | AB32: 46213 | AC32: =IF(I32=1,N32-AB32,Overview!$B$5-AB32) -> 90 | AD32: ABA sample CSV | AE32: 0 | AF32: 0 | AG32: 0 | AH32: 0 | AI32: 1 | AJ32: 1 | AK32: 1 | AL32: 0 | AM32: 0 | AN32: 0 | AO32: 0 | AP32: 0 | AQ32: 1 | AR32: 0 | AS32: 0 | AT32: 1 | AU32: 0 | AV32: 0 | AW32: 0 | AX32: 0
